Fixed the behaviour of validate_user function in validations.py.

Closes:#1

Fixes#<issue_number_goes_here>

>It's a good idea to open an issue first for discussion.

-[] Tests pass

